2018-03-15 18:35:03,956 ERROR: Exception on /edit_profile [GET] [in c:\python27\lib\site-packages\flask\app.py:1560]
Traceback (most recent call last):
  File "c:\python27\lib\site-packages\flask\app.py", line 1982, in wsgi_app
    response = self.full_dispatch_request()
  File "c:\python27\lib\site-packages\flask\app.py", line 1614, in full_dispatch_request
    rv = self.handle_user_exception(e)
  File "c:\python27\lib\site-packages\flask\app.py", line 1517, in handle_user_exception
    reraise(exc_type, exc_value, tb)
  File "c:\python27\lib\site-packages\flask\app.py", line 1612, in full_dispatch_request
    rv = self.dispatch_request()
  File "c:\python27\lib\site-packages\flask\app.py", line 1598, in dispatch_request
    return self.view_functions[rule.endpoint](**req.view_args)
  File "c:\python27\lib\site-packages\flask_login\utils.py", line 261, in decorated_view
    return func(*args, **kwargs)
  File "C:\Users\armag\OneDrive\Documents\GitHub\Bedouina\www\b3na_web_bottle\app\routes.py", line 99, in edit_profile
    form.email.data = current.user.email
NameError: global name 'current' is not defined
2018-03-15 18:35:49,927 INFO: B3na web startup [in C:\Users\armag\OneDrive\Documents\GitHub\Bedouina\www\b3na_web_bottle\app\__init__.py:46]
2018-03-15 18:36:41,187 INFO: B3na web startup [in C:\Users\armag\OneDrive\Documents\GitHub\Bedouina\www\b3na_web_bottle\app\__init__.py:46]
2018-03-15 18:38:00,908 ERROR: Exception on /device/00:50:f1:80:00:00 [POST] [in c:\python27\lib\site-packages\flask\app.py:1560]
Traceback (most recent call last):
  File "c:\python27\lib\site-packages\flask\app.py", line 1982, in wsgi_app
    response = self.full_dispatch_request()
  File "c:\python27\lib\site-packages\flask\app.py", line 1614, in full_dispatch_request
    rv = self.handle_user_exception(e)
  File "c:\python27\lib\site-packages\flask\app.py", line 1517, in handle_user_exception
    reraise(exc_type, exc_value, tb)
  File "c:\python27\lib\site-packages\flask\app.py", line 1612, in full_dispatch_request
    rv = self.dispatch_request()
  File "c:\python27\lib\site-packages\flask\app.py", line 1598, in dispatch_request
    return self.view_functions[rule.endpoint](**req.view_args)
  File "c:\python27\lib\site-packages\flask_login\utils.py", line 261, in decorated_view
    return func(*args, **kwargs)
  File "C:\Users\armag\OneDrive\Documents\GitHub\Bedouina\www\b3na_web_bottle\app\routes.py", line 113, in edit_device
    device.device_type=DeviceTypes.query.filter_by(type=request.form['types']).first().id
  File "c:\python27\lib\site-packages\sqlalchemy\orm\attributes.py", line 229, in __set__
    instance_dict(instance), value, None)
  File "c:\python27\lib\site-packages\sqlalchemy\orm\attributes.py", line 813, in set
    value = self.fire_replace_event(state, dict_, value, old, initiator)
  File "c:\python27\lib\site-packages\sqlalchemy\orm\attributes.py", line 833, in fire_replace_event
    state, value, previous, initiator or self._replace_token)
  File "c:\python27\lib\site-packages\sqlalchemy\orm\unitofwork.py", line 88, in set_
    newvalue_state = attributes.instance_state(newvalue)
AttributeError: 'long' object has no attribute '_sa_instance_state'
2018-03-15 18:38:56,507 INFO: B3na web startup [in C:\Users\armag\OneDrive\Documents\GitHub\Bedouina\www\b3na_web_bottle\app\__init__.py:46]
2018-03-15 18:39:05,598 ERROR: Exception on /device/00:50:f1:80:00:00 [POST] [in c:\python27\lib\site-packages\flask\app.py:1560]
Traceback (most recent call last):
  File "c:\python27\lib\site-packages\flask\app.py", line 1982, in wsgi_app
    response = self.full_dispatch_request()
  File "c:\python27\lib\site-packages\flask\app.py", line 1614, in full_dispatch_request
    rv = self.handle_user_exception(e)
  File "c:\python27\lib\site-packages\flask\app.py", line 1517, in handle_user_exception
    reraise(exc_type, exc_value, tb)
  File "c:\python27\lib\site-packages\flask\app.py", line 1612, in full_dispatch_request
    rv = self.dispatch_request()
  File "c:\python27\lib\site-packages\flask\app.py", line 1598, in dispatch_request
    return self.view_functions[rule.endpoint](**req.view_args)
  File "c:\python27\lib\site-packages\flask_login\utils.py", line 261, in decorated_view
    return func(*args, **kwargs)
  File "C:\Users\armag\OneDrive\Documents\GitHub\Bedouina\www\b3na_web_bottle\app\routes.py", line 113, in edit_device
    device.device_type=DeviceTypes.query.filter_by(type=request.form['types']).first().id
  File "c:\python27\lib\site-packages\sqlalchemy\orm\attributes.py", line 229, in __set__
    instance_dict(instance), value, None)
  File "c:\python27\lib\site-packages\sqlalchemy\orm\attributes.py", line 813, in set
    value = self.fire_replace_event(state, dict_, value, old, initiator)
  File "c:\python27\lib\site-packages\sqlalchemy\orm\attributes.py", line 833, in fire_replace_event
    state, value, previous, initiator or self._replace_token)
  File "c:\python27\lib\site-packages\sqlalchemy\orm\unitofwork.py", line 88, in set_
    newvalue_state = attributes.instance_state(newvalue)
AttributeError: 'long' object has no attribute '_sa_instance_state'
2018-03-15 18:39:15,423 ERROR: Exception on /device/00:50:f1:80:00:00 [POST] [in c:\python27\lib\site-packages\flask\app.py:1560]
Traceback (most recent call last):
  File "c:\python27\lib\site-packages\flask\app.py", line 1982, in wsgi_app
    response = self.full_dispatch_request()
  File "c:\python27\lib\site-packages\flask\app.py", line 1614, in full_dispatch_request
    rv = self.handle_user_exception(e)
  File "c:\python27\lib\site-packages\flask\app.py", line 1517, in handle_user_exception
    reraise(exc_type, exc_value, tb)
  File "c:\python27\lib\site-packages\flask\app.py", line 1612, in full_dispatch_request
    rv = self.dispatch_request()
  File "c:\python27\lib\site-packages\flask\app.py", line 1598, in dispatch_request
    return self.view_functions[rule.endpoint](**req.view_args)
  File "c:\python27\lib\site-packages\flask_login\utils.py", line 261, in decorated_view
    return func(*args, **kwargs)
  File "C:\Users\armag\OneDrive\Documents\GitHub\Bedouina\www\b3na_web_bottle\app\routes.py", line 113, in edit_device
    device.device_type=DeviceTypes.query.filter_by(type=request.form['types']).first().id
  File "c:\python27\lib\site-packages\sqlalchemy\orm\attributes.py", line 229, in __set__
    instance_dict(instance), value, None)
  File "c:\python27\lib\site-packages\sqlalchemy\orm\attributes.py", line 813, in set
    value = self.fire_replace_event(state, dict_, value, old, initiator)
  File "c:\python27\lib\site-packages\sqlalchemy\orm\attributes.py", line 833, in fire_replace_event
    state, value, previous, initiator or self._replace_token)
  File "c:\python27\lib\site-packages\sqlalchemy\orm\unitofwork.py", line 88, in set_
    newvalue_state = attributes.instance_state(newvalue)
AttributeError: 'long' object has no attribute '_sa_instance_state'
2018-03-15 18:39:59,111 INFO: B3na web startup [in C:\Users\armag\OneDrive\Documents\GitHub\Bedouina\www\b3na_web_bottle\app\__init__.py:46]
2018-03-15 18:40:07,592 ERROR: Exception on /device/00:50:f1:80:00:00 [POST] [in c:\python27\lib\site-packages\flask\app.py:1560]
Traceback (most recent call last):
  File "c:\python27\lib\site-packages\flask\app.py", line 1982, in wsgi_app
    response = self.full_dispatch_request()
  File "c:\python27\lib\site-packages\flask\app.py", line 1614, in full_dispatch_request
    rv = self.handle_user_exception(e)
  File "c:\python27\lib\site-packages\flask\app.py", line 1517, in handle_user_exception
    reraise(exc_type, exc_value, tb)
  File "c:\python27\lib\site-packages\flask\app.py", line 1612, in full_dispatch_request
    rv = self.dispatch_request()
  File "c:\python27\lib\site-packages\flask\app.py", line 1598, in dispatch_request
    return self.view_functions[rule.endpoint](**req.view_args)
  File "c:\python27\lib\site-packages\flask_login\utils.py", line 261, in decorated_view
    return func(*args, **kwargs)
  File "C:\Users\armag\OneDrive\Documents\GitHub\Bedouina\www\b3na_web_bottle\app\routes.py", line 114, in edit_device
    device.device_type=DeviceTypes.query.filter_by(type=request.form['types']).first().id
  File "c:\python27\lib\site-packages\sqlalchemy\orm\attributes.py", line 229, in __set__
    instance_dict(instance), value, None)
  File "c:\python27\lib\site-packages\sqlalchemy\orm\attributes.py", line 813, in set
    value = self.fire_replace_event(state, dict_, value, old, initiator)
  File "c:\python27\lib\site-packages\sqlalchemy\orm\attributes.py", line 833, in fire_replace_event
    state, value, previous, initiator or self._replace_token)
  File "c:\python27\lib\site-packages\sqlalchemy\orm\unitofwork.py", line 88, in set_
    newvalue_state = attributes.instance_state(newvalue)
AttributeError: 'long' object has no attribute '_sa_instance_state'
2018-03-15 18:41:10,582 INFO: B3na web startup [in C:\Users\armag\OneDrive\Documents\GitHub\Bedouina\www\b3na_web_bottle\app\__init__.py:46]
